2025-05-21 19:52:58,893 fail2ban.server         [1]: INFO    Shutdown in progress...
2025-05-21 19:52:59,057 fail2ban.observer       [1]: INFO    Observer stop ... try to end queue 5 seconds
2025-05-21 19:52:59,109 fail2ban.observer       [1]: INFO    Observer stopped, 0 events remaining.
2025-05-21 19:52:59,150 fail2ban.server         [1]: INFO    Stopping all jails
2025-05-21 19:52:59,295 fail2ban.filter         [1]: INFO    Removed logfile: '/var/log/apache2/access.log'
2025-05-21 19:52:59,388 fail2ban.actions        [1]: NOTICE  [apache-auth] Flush ticket(s) with iptables-multiport
2025-05-21 19:52:59,936 fail2ban.jail           [1]: INFO    Jail 'apache-auth' stopped
2025-05-21 19:52:59,969 fail2ban.database       [1]: INFO    Connection to database closed.
2025-05-21 19:52:59,984 fail2ban.server         [1]: INFO    Exiting Fail2ban
2025-05-21 19:55:15,485 fail2ban.server         [1]: INFO    --------------------------------------------------
2025-05-21 19:55:15,486 fail2ban.server         [1]: INFO    Starting Fail2ban v0.11.2
2025-05-21 19:55:15,489 fail2ban.observer       [1]: INFO    Observer start...
2025-05-21 19:55:15,506 fail2ban.database       [1]: INFO    Connected to fail2ban persistent database '/var/lib/fail2ban/fail2ban.sqlite3'
2025-05-21 19:55:15,518 fail2ban.database       [1]: WARNING New database created. Version '4'
2025-05-21 19:55:15,525 fail2ban.transmitter    [1]: ERROR   Jail 'sshd' skipped, because of wrong configuration: Unable to read the filter 'sshd'
2025-05-21 19:55:15,525 fail2ban.jail           [1]: INFO    Creating new jail 'apache-auth'
2025-05-21 19:55:15,602 fail2ban.jail           [1]: INFO    Jail 'apache-auth' uses pyinotify {}
2025-05-21 19:55:15,615 fail2ban.jail           [1]: INFO    Initiated 'pyinotify' backend
2025-05-21 19:55:15,627 fail2ban.filter         [1]: INFO      maxRetry: 3
2025-05-21 19:55:15,627 fail2ban.filter         [1]: INFO      findtime: 600
2025-05-21 19:55:15,627 fail2ban.actions        [1]: INFO      banTime: 3600
2025-05-21 19:55:15,627 fail2ban.filter         [1]: INFO      encoding: UTF-8
2025-05-21 19:55:15,631 fail2ban.filter         [1]: INFO    Added logfile: '/var/log/apache2/access.log' (pos = 0, hash = ecc3d391cd3bb2d0438610f87c91dbbca38a1251)
2025-05-21 19:55:15,647 fail2ban.jail           [1]: INFO    Jail 'apache-auth' started
2025-05-21 19:58:49,445 fail2ban.server         [1]: INFO    Shutdown in progress...
2025-05-21 19:58:49,644 fail2ban.observer       [1]: INFO    Observer stop ... try to end queue 5 seconds
2025-05-21 19:58:49,744 fail2ban.observer       [1]: INFO    Observer stopped, 0 events remaining.
2025-05-21 19:58:49,806 fail2ban.server         [1]: INFO    Stopping all jails
2025-05-21 19:58:49,928 fail2ban.filter         [1]: INFO    Removed logfile: '/var/log/apache2/access.log'
2025-05-21 19:58:50,066 fail2ban.actions        [1]: NOTICE  [apache-auth] Flush ticket(s) with iptables-multiport
2025-05-21 19:58:50,208 fail2ban.jail           [1]: INFO    Jail 'apache-auth' stopped
2025-05-21 19:58:50,253 fail2ban.database       [1]: INFO    Connection to database closed.
2025-05-21 19:58:50,269 fail2ban.server         [1]: INFO    Exiting Fail2ban
2025-05-21 20:00:46,335 fail2ban.server         [1]: INFO    --------------------------------------------------
2025-05-21 20:00:46,335 fail2ban.server         [1]: INFO    Starting Fail2ban v0.11.2
2025-05-21 20:00:46,340 fail2ban.observer       [1]: INFO    Observer start...
2025-05-21 20:00:46,352 fail2ban.database       [1]: INFO    Connected to fail2ban persistent database '/var/lib/fail2ban/fail2ban.sqlite3'
2025-05-21 20:00:46,360 fail2ban.database       [1]: WARNING New database created. Version '4'
2025-05-21 20:00:46,362 fail2ban.transmitter    [1]: ERROR   Jail 'sshd' skipped, because of wrong configuration: Unable to read the filter 'sshd'
2025-05-21 20:00:46,362 fail2ban.jail           [1]: INFO    Creating new jail 'apache-auth'
2025-05-21 20:00:46,452 fail2ban.jail           [1]: INFO    Jail 'apache-auth' uses pyinotify {}
2025-05-21 20:00:46,471 fail2ban.jail           [1]: INFO    Initiated 'pyinotify' backend
2025-05-21 20:00:46,473 fail2ban.filter         [1]: INFO      maxRetry: 3
2025-05-21 20:00:46,474 fail2ban.filter         [1]: INFO      findtime: 600
2025-05-21 20:00:46,474 fail2ban.actions        [1]: INFO      banTime: 3600
2025-05-21 20:00:46,474 fail2ban.filter         [1]: INFO      encoding: UTF-8
2025-05-21 20:00:46,480 fail2ban.filter         [1]: INFO    Added logfile: '/var/log/apache2/access.log' (pos = 0, hash = ecc3d391cd3bb2d0438610f87c91dbbca38a1251)
2025-05-21 20:00:46,501 fail2ban.jail           [1]: INFO    Jail 'apache-auth' started
2025-05-21 20:05:45,051 fail2ban.filter         [1]: INFO    [apache-auth] Found 192.168.58.1 - 2025-05-21 20:05:44
2025-05-21 20:05:47,821 fail2ban.filter         [1]: INFO    [apache-auth] Found 192.168.58.1 - 2025-05-21 20:05:47
2025-05-21 20:05:50,531 fail2ban.filter         [1]: INFO    [apache-auth] Found 192.168.58.1 - 2025-05-21 20:05:50
2025-05-21 20:05:51,040 fail2ban.actions        [1]: NOTICE  [apache-auth] Ban 192.168.58.1
2025-05-21 20:05:51,131 fail2ban.utils          [1]: ERROR   79c8ce528ed0 -- exec: iptables -w -N f2b-apache-auth
iptables -w -A f2b-apache-auth -j RETURN
iptables -w -I INPUT -p tcp -m multiport --dports http,https -j f2b-apache-auth
2025-05-21 20:05:51,132 fail2ban.utils          [1]: ERROR   79c8ce528ed0 -- stderr: '/bin/sh: 1: iptables: not found'
2025-05-21 20:05:51,132 fail2ban.utils          [1]: ERROR   79c8ce528ed0 -- stderr: '/bin/sh: 2: iptables: not found'
2025-05-21 20:05:51,132 fail2ban.utils          [1]: ERROR   79c8ce528ed0 -- stderr: '/bin/sh: 3: iptables: not found'
2025-05-21 20:05:51,132 fail2ban.utils          [1]: ERROR   79c8ce528ed0 -- returned 127
2025-05-21 20:05:51,133 fail2ban.utils          [1]: INFO    HINT on 127: "Command not found".  Make sure that all commands in 'iptables -w -N f2b-apache-auth\niptables -w -A f2b-apache-auth -j RETURN\niptables -w -I INPUT -p tcp -m multiport --dports http,https -j f2b-apache-auth' are in the PATH of fail2ban-server process (grep -a PATH= /proc/`pidof -x fail2ban-server`/environ). You may want to start "fail2ban-server -f" separately, initiate it with "fail2ban-client reload" in another shell session and observe if additional informative error messages appear in the terminals.
2025-05-21 20:05:51,133 fail2ban.actions        [1]: ERROR   Failed to execute ban jail 'apache-auth' action 'iptables-multiport' info 'ActionInfo({'ip': '192.168.58.1', 'family': 'inet4', 'fid': <function Actions.ActionInfo.<lambda> at 0x79c8cee94430>, 'raw-ticket': <function Actions.ActionInfo.<lambda> at 0x79c8cee94af0>})': Error starting action Jail('apache-auth')/iptables-multiport: 'Script error'
2025-05-21 20:05:52,142 fail2ban.filter         [1]: INFO    [apache-auth] Found 192.168.58.1 - 2025-05-21 20:05:51
2025-05-21 20:08:48,770 fail2ban.server         [1]: INFO    Shutdown in progress...
2025-05-21 20:08:48,773 fail2ban.observer       [1]: INFO    Observer stop ... try to end queue 5 seconds
2025-05-21 20:08:48,795 fail2ban.observer       [1]: INFO    Observer stopped, 0 events remaining.
2025-05-21 20:08:48,838 fail2ban.server         [1]: INFO    Stopping all jails
2025-05-21 20:08:48,845 fail2ban.filter         [1]: INFO    Removed logfile: '/var/log/apache2/access.log'
2025-05-21 20:08:49,436 fail2ban.actions        [1]: NOTICE  [apache-auth] Flush ticket(s) with iptables-multiport
2025-05-21 20:08:49,436 fail2ban.actions        [1]: NOTICE  [apache-auth] Unban 192.168.58.1
2025-05-21 20:08:49,439 fail2ban.jail           [1]: INFO    Jail 'apache-auth' stopped
2025-05-21 20:08:49,445 fail2ban.database       [1]: INFO    Connection to database closed.
2025-05-21 20:08:49,449 fail2ban.server         [1]: INFO    Exiting Fail2ban
2025-05-21 20:11:06,880 fail2ban.server         [1]: INFO    --------------------------------------------------
2025-05-21 20:11:06,886 fail2ban.server         [1]: INFO    Starting Fail2ban v0.11.2
2025-05-21 20:11:06,892 fail2ban.observer       [1]: INFO    Observer start...
2025-05-21 20:11:06,933 fail2ban.database       [1]: INFO    Connected to fail2ban persistent database '/var/lib/fail2ban/fail2ban.sqlite3'
2025-05-21 20:11:06,947 fail2ban.database       [1]: WARNING New database created. Version '4'
2025-05-21 20:11:06,950 fail2ban.transmitter    [1]: ERROR   Jail 'sshd' skipped, because of wrong configuration: Unable to read the filter 'sshd'
2025-05-21 20:11:06,952 fail2ban.jail           [1]: INFO    Creating new jail 'apache-auth'
2025-05-21 20:11:07,017 fail2ban.jail           [1]: INFO    Jail 'apache-auth' uses pyinotify {}
2025-05-21 20:11:07,042 fail2ban.jail           [1]: INFO    Initiated 'pyinotify' backend
2025-05-21 20:11:07,045 fail2ban.filter         [1]: INFO      maxRetry: 3
2025-05-21 20:11:07,045 fail2ban.filter         [1]: INFO      findtime: 600
2025-05-21 20:11:07,045 fail2ban.actions        [1]: INFO      banTime: 3600
2025-05-21 20:11:07,045 fail2ban.filter         [1]: INFO      encoding: UTF-8
2025-05-21 20:11:07,048 fail2ban.filter         [1]: INFO    Added logfile: '/var/log/apache2/access.log' (pos = 0, hash = ecc3d391cd3bb2d0438610f87c91dbbca38a1251)
2025-05-21 20:11:07,068 fail2ban.jail           [1]: INFO    Jail 'apache-auth' started
2025-05-21 20:11:07,167 fail2ban.filter         [1]: INFO    [apache-auth] Found 192.168.58.1 - 2025-05-21 20:05:44
2025-05-21 20:11:07,172 fail2ban.filter         [1]: INFO    [apache-auth] Found 192.168.58.1 - 2025-05-21 20:05:47
2025-05-21 20:11:07,175 fail2ban.filter         [1]: INFO    [apache-auth] Found 192.168.58.1 - 2025-05-21 20:05:50
2025-05-21 20:11:07,179 fail2ban.filter         [1]: INFO    [apache-auth] Found 192.168.58.1 - 2025-05-21 20:05:51
2025-05-21 20:11:07,267 fail2ban.actions        [1]: NOTICE  [apache-auth] Ban 192.168.58.1
2025-05-21 20:11:07,310 fail2ban.utils          [1]: ERROR   714eec415070 -- exec: iptables -w -N f2b-apache-auth
iptables -w -A f2b-apache-auth -j RETURN
iptables -w -I INPUT -p tcp -m multiport --dports http,https -j f2b-apache-auth
2025-05-21 20:11:07,317 fail2ban.utils          [1]: ERROR   714eec415070 -- stderr: '/bin/sh: 1: iptables: not found'
2025-05-21 20:11:07,317 fail2ban.utils          [1]: ERROR   714eec415070 -- stderr: '/bin/sh: 2: iptables: not found'
2025-05-21 20:11:07,317 fail2ban.utils          [1]: ERROR   714eec415070 -- stderr: '/bin/sh: 3: iptables: not found'
2025-05-21 20:11:07,317 fail2ban.utils          [1]: ERROR   714eec415070 -- returned 127
2025-05-21 20:11:07,317 fail2ban.utils          [1]: INFO    HINT on 127: "Command not found".  Make sure that all commands in 'iptables -w -N f2b-apache-auth\niptables -w -A f2b-apache-auth -j RETURN\niptables -w -I INPUT -p tcp -m multiport --dports http,https -j f2b-apache-auth' are in the PATH of fail2ban-server process (grep -a PATH= /proc/`pidof -x fail2ban-server`/environ). You may want to start "fail2ban-server -f" separately, initiate it with "fail2ban-client reload" in another shell session and observe if additional informative error messages appear in the terminals.
2025-05-21 20:11:07,318 fail2ban.actions        [1]: ERROR   Failed to execute ban jail 'apache-auth' action 'iptables-multiport' info 'ActionInfo({'ip': '192.168.58.1', 'family': 'inet4', 'fid': <function Actions.ActionInfo.<lambda> at 0x714eecd80430>, 'raw-ticket': <function Actions.ActionInfo.<lambda> at 0x714eecd80af0>})': Error starting action Jail('apache-auth')/iptables-multiport: 'Script error'
